<?xml version="1.0" encoding="utf-8"?>
<robot name="rm_65_description" xmlns:xacro="http://www.ros.org/wiki/xacro">
<!-- link6_type -->
<xacro:arg name="link6_type" default="Link6" />
<!-- arg->property -->
<xacro:property name="link6_type" value="$(arg link6_type)" />
  <link
    name="base_link">
    <inertial>
      <origin
        xyz="-0.000433277303987328 -3.54664423471128E-05 0.0599427668933796"
        rpy="0 0 0" />
      <mass
        value="0.841070778135659" />
      <!-- <inertia
        ixx="0.0017261110801622"
        ixy="2.52746264980217E-06"
        ixz="-3.67690303614961E-05"
        iyy="0.00170987405835604"
        iyz="1.67996364994424E-06"
        izz="0.000904023422915791" />
    </inertial> -->
    <inertia
        ixx="0"
        ixy="0"
        ixz="0"
        iyy="0"
        iyz="0"
        izz="0" />
    </inertial>
    <visual>
      <origin
        xyz="0 0 0"
        rpy="0 0 0" />
      <geometry>
        <mesh
          filename="file://$(find rm_description)/meshes/rm_65_arm/base_link.STL" />
      </geometry>
      <material
        name="">
        <color
          rgba="1 1 1 1" />
      </material>
    </visual>
    <collision>
      <origin
        xyz="0 0 0"
        rpy="0 0 0" />
      <geometry>
        <mesh
          filename="file://$(find rm_description)/meshes/rm_65_arm/base_link.STL" />
      </geometry>
    </collision>
  </link>
  <link
    name="Link1">
    <inertial>
      <origin
        xyz="1.2226305431569E-08 0.0211079974844683 -0.0251854220842269"
        rpy="0 0 0" />
      <mass
        value="0.593563443690403" />
      <!-- <inertia
        ixx="0.00126614120341847"
        ixy="-1.294980943835E-08"
        ixz="-9.80120923066996E-09"
        iyy="0.00118168178300364"
        iyz="-0.00021121727444415"
        izz="0.00056135241627747" />
    </inertial> -->
    <inertia
        ixx="0"
        ixy="0"
        ixz="0"
        iyy="0"
        iyz="0"
        izz="0" />
    </inertial>
    <visual>
      <origin
        xyz="0 0 0"
        rpy="0 0 0" />
      <geometry>
        <mesh
          filename="file://$(find rm_description)/meshes/rm_65_arm/link1.STL" />
      </geometry>
      <material
        name="">
        <color
          rgba="1 1 1 1" />
      </material>
    </visual>
    <collision>
      <origin
        xyz="0 0 0"
        rpy="0 0 0" />
      <geometry>
        <mesh
          filename="file://$(find rm_description)/meshes/rm_65_arm/link1.STL" />
      </geometry>
    </collision>
  </link>
  <joint
    name="joint1"
    type="revolute">
    <origin
      xyz="0 0 0.2405"
      rpy="0 0 0" />
    <parent
      link="base_link" />
    <child
      link="Link1" />
    <axis
      xyz="0 0 1" />
    <limit
      lower="-3.1"
      upper="3.1"
      effort="60"
      velocity="3.14" />
  </joint>
  <link
    name="Link2">
    <inertial>
      <origin
        xyz="0.152256463426163 4.75383656106654E-07 -0.00620260383607792"
        rpy="0 0 0" />
      <mass
        value="0.864175046869043" />
      <!-- <inertia
        ixx="0.00089150298478414"
        ixy="-2.23268489334765E-08"
        ixz="0.00156246461035015"
        iyy="0.00733754343083901"
        iyz="6.28110889329165E-09"
        izz="0.00697869103915473" />
    </inertial> -->
    <inertia
        ixx="0"
        ixy="0"
        ixz="0"
        iyy="0"
        iyz="0"
        izz="0" />
    </inertial>
    <visual>
      <origin
        xyz="0 0 0"
        rpy="0 0 0" />
      <geometry>
        <mesh
          filename="file://$(find rm_description)/meshes/rm_65_arm/link2.STL" />
      </geometry>
      <material
        name="">
        <color
          rgba="1 1 1 1" />
      </material>
    </visual>
    <collision>
      <origin
        xyz="0 0 0"
        rpy="0 0 0" />
      <geometry>
        <mesh
          filename="file://$(find rm_description)/meshes/rm_65_arm/link2.STL" />
      </geometry>
    </collision>
  </link>
  <joint
    name="joint2"
    type="revolute">
    <origin
      xyz="0 0 0"
      rpy="1.5708 -1.5708 0" />
    <parent
      link="Link1" />
    <child
      link="Link2" />
    <axis
      xyz="0 0 1" />
    <limit
      lower="-2.268"
      upper="2.268"
      effort="60"
      velocity="3.14" />
  </joint>
  <link
    name="Link3">
    <inertial>
      <origin
        xyz="5.05312670989961E-06 -0.0595925663694732 0.010569069212336"
        rpy="0 0 0" />
      <mass
        value="0.289633681624654" />
      <!-- <inertia
        ixx="0.00063737100450158"
        ixy="-7.05261293649751E-08"
        ixz="-3.86643272239426E-08"
        iyy="0.00015648388095025"
        iyz="-0.00014461035994916"
        izz="0.000614178164773085" />
    </inertial> -->
    <inertia
        ixx="0"
        ixy="0"
        ixz="0"
        iyy="0"
        iyz="0"
        izz="0" />
    </inertial>
    <visual>
      <origin
        xyz="0 0 0"
        rpy="0 0 0" />
      <geometry>
        <mesh
          filename="file://$(find rm_description)/meshes/rm_65_arm/link3.STL" />
      </geometry>
      <material
        name="">
        <color
          rgba="1 1 1 1" />
      </material>
    </visual>
    <collision>
      <origin
        xyz="0 0 0"
        rpy="0 0 0" />
      <geometry>
        <mesh
          filename="file://$(find rm_description)/meshes/rm_65_arm/link3.STL" />
      </geometry>
    </collision>
  </link>
  <joint
    name="joint3"
    type="revolute">
    <origin
      xyz="0.256 0 0"
      rpy="0 0 1.5708" />
    <parent
      link="Link2" />
    <child
      link="Link3" />
    <axis
      xyz="0 0 1" />
    <limit
      lower="-2.355"
      upper="2.355"
      effort="30"
      velocity="3.92" />
  </joint>
  <link
    name="Link4">
    <inertial>
      <origin
        xyz="1.15516617405898E-06 -0.0180424468598241 -0.0215394748352687"
        rpy="0 0 0" />
      <mass
        value="0.239419768320061" />
      <!-- <inertia
        ixx="0.000285938919722783"
        ixy="3.07101359163101E-09"
        ixz="-2.21994118981953E-09"
        iyy="0.000262727540304212"
        iyz="4.4236583260078E-05"
        izz="0.000119888082791859" />
    </inertial>-->
    <inertia
        ixx="0"
        ixy="0"
        ixz="0"
        iyy="0"
        iyz="0"
        izz="0" />
    </inertial>
    <visual>
      <origin
        xyz="0 0 0"
        rpy="0 0 0" />
      <geometry>
        <mesh
          filename="file://$(find rm_description)/meshes/rm_65_arm/link4.STL" />
      </geometry>
      <material
        name="">
        <color
          rgba="1 1 1 1" />
      </material>
    </visual>
    <collision>
      <origin
        xyz="0 0 0"
        rpy="0 0 0" />
      <geometry>
        <mesh
          filename="file://$(find rm_description)/meshes/rm_65_arm/link4.STL" />
      </geometry>
    </collision>
  </link>
  <joint
    name="joint4"
    type="revolute">
    <origin
      xyz="0 -0.21 0"
      rpy="1.5708 0 0" />
    <parent
      link="Link3" />
    <child
      link="Link4" />
    <axis
      xyz="0 0 1" />
    <limit
      lower="-3.1"
      upper="3.1"
      effort="10"
      velocity="3.92" />
  </joint>
  <link
    name="Link5">
    <inertial>
      <origin
        xyz="3.19794786262152E-06 -0.0593808368101458 0.00736804250989326"
        rpy="0 0 0" />
      <mass
        value="0.218799761431678" />
      <!-- <inertia
        ixx="0.000350540363914072"
        ixy="-3.41781619975602E-08"
        ixz="-1.77056457224373E-08"
        iyy="0.000104927867487581"
        iyz="-7.82431228461971E-05"
        izz="0.000334482418423629" />
    </inertial> -->
    <inertia
        ixx="0"
        ixy="0"
        ixz="0"
        iyy="0"
        iyz="0"
        izz="0" />
    </inertial>
    <visual>
      <origin
        xyz="0 0 0"
        rpy="0 0 0" />
      <geometry>
        <mesh
          filename="file://$(find rm_description)/meshes/rm_65_arm/link5.STL" />
      </geometry>
      <material
        name="">
        <color
          rgba="1 1 1 1" />
      </material>
    </visual>
    <collision>
      <origin
        xyz="0 0 0"
        rpy="0 0 0" />
      <geometry>
        <mesh
          filename="file://$(find rm_description)/meshes/rm_65_arm/link5.STL" />
      </geometry>
    </collision>
  </link>
  <joint
    name="joint5"
    type="revolute">
    <origin
      xyz="0 0 0"
      rpy="-1.5708 0 0" />
    <parent
      link="Link4" />
    <child
      link="Link5" />
    <axis
      xyz="0 0 1" />
    <limit
      lower="-2.233"
      upper="2.233"
      effort="10"
      velocity="3.92" />
  </joint>
  <xacro:if value="${ link6_type =='Link6' }">
    <link
      name="Link6">
      <inertial>
        <origin
          xyz="0.000714234511756999 -0.000396718732824521 -0.0126723660946126"
          rpy="0 0 0" />
        <mass
          value="0.0649018034311231" />
        <!-- <inertia
          ixx="2.02766547502765E-05"
          ixy="-1.32505200276849E-06"
          ixz="-2.5845091522508E-08"
          iyy="1.87986725225022E-05"
          iyz="3.39471452125439E-09"
          izz="3.17885459163081E-05" />
      </inertial> -->
      <inertia
        ixx="0"
        ixy="0"
        ixz="0"
        iyy="0"
        iyz="0"
        izz="0" />
    </inertial>
      <visual>
        <origin
          xyz="0 0 0"
          rpy="0 0 0" />
        <geometry>
          <mesh
            filename="file://$(find rm_description)/meshes/rm_65_arm/link6.STL" />
        </geometry>
        <material
          name="">
          <color
            rgba="1 1 1 1" />
        </material>
      </visual>
      <collision>
        <origin
          xyz="0 0 0"
          rpy="0 0 0" />
        <geometry>
          <mesh
            filename="file://$(find rm_description)/meshes/rm_65_arm/link6.STL" />
        </geometry>
      </collision>
    </link>
    <joint
      name="joint6"
      type="revolute">
      <origin
        xyz="0 -0.144 0"
        rpy="1.5708 0 0" />
      <parent
        link="Link5" />
      <child
        link="Link6" />
      <axis
        xyz="0 0 1" />
      <limit
        lower="-6.28"
        upper="6.28"
        effort="10"
        velocity="3.92" />
    </joint>
  </xacro:if>
  <xacro:if value="${ link6_type =='Link6_6f' }">
    <link
    name="Link6">
    <inertial>
      <origin
        xyz="0.00032231 -0.00017819 -0.028676"
        rpy="0 0 0" />
      <mass
        value="0.14433" />
      <!-- <inertia
        ixx="3.6119E-05"
        ixy="-1.3242E-06"
        ixz="-3.2733E-08"
        iyy="3.4626E-05"
        iyz="7.6661E-09"
        izz="6.1463E-05" />
      </inertial> -->
      <inertia
        ixx="0"
        ixy="0"
        ixz="0"
        iyy="0"
        iyz="0"
        izz="0" />
      </inertial>
      <visual>
        <origin
          xyz="0 0 0"
          rpy="0 0 0" />
        <geometry>
          <mesh
            filename="file://$(find rm_description)/meshes/rm_65_arm/link6_6f.STL" />
        </geometry>
        <material
          name="">
          <color
            rgba="1 1 1 1" />
        </material>
      </visual>
      <collision>
        <origin
          xyz="0 0 0"
          rpy="0 0 0" />
        <geometry>
          <mesh
            filename="file://$(find rm_description)/meshes/rm_65_arm/link6_6f.STL" />
        </geometry>
      </collision>
    </link>
    <joint
      name="joint6"
      type="revolute">
      <origin
        xyz="0 -0.1725 0"
        rpy="1.5708 0 0" />
      <parent
        link="Link5" />
      <child
        link="Link6" />
      <axis
        xyz="0 0 1" />
      <limit
        lower="-6.283"
        upper="6.283"
        effort="100"
        velocity="1" />
    </joint>
  </xacro:if>
  <xacro:if value="${ link6_type =='Link6_6fb' }">
    <link
      name="Link6">
      <inertial>
        <origin
          xyz="0.000138559985614397 -0.00574537418929974 -0.535986173384404"
          rpy="0 0 0" />
        <mass
          value="3.04449097371379" />
        <!-- <inertia
          ixx="0.170810328289537"
          ixy="5.3822775672348E-07"
          ixz="0.000151207460728544"
          iyy="0.169967421523245"
          iyz="0.00105777172655597"
          izz="0.00305546066386606" />
      </inertial> -->
      <inertia
        ixx="0"
        ixy="0"
        ixz="0"
        iyy="0"
        iyz="0"
        izz="0" />
      </inertial>
      <visual>
        <origin
          xyz="0 0 0"
          rpy="0 0 0" />
        <geometry>
          <mesh
            filename="file://$(find rm_description)/meshes/rm_65_arm/link6_6fb.STL" />
        </geometry>
        <material
          name="">
          <color
            rgba="0.792156862745098 0.819607843137255 0.933333333333333 1" />
        </material>
      </visual>
      <collision>
        <origin
          xyz="0 0 0"
          rpy="0 0 0" />
        <geometry>
          <mesh
            filename="file://$(find rm_description)/meshes/rm_65_arm/link6_6fb.STL" />
        </geometry>
      </collision>
    </link>
    <joint
      name="joint6"
      type="revolute">
      <origin
        xyz="0 -0.1613 0"
        rpy="1.5708 0 0" />
      <parent
        link="Link5" />
      <child
        link="Link6" />
      <axis
        xyz="0 0 1" />
      <limit
        lower="-6.28"
        upper="6.28"
        effort="10"
        velocity="3.14" />
    </joint>
  </xacro:if>

  <!-- 相机扩展 -->
  <link name="camera_connection">
    <visual>
      <origin xyz="0 0 0" rpy="0 0 0" />
      <geometry>
        <box size="0.02 0.06 0.02" />
      </geometry>
      <material name="black">
        <color rgba="0.0 0.0 0.0 0.8" />
      </material>
    </visual>
    <collision>
      <origin xyz="0 0 0" rpy="0 0 0" />
      <geometry>
        <box size="0.02 0.06 0.02" />
      </geometry>
      <material name="black">
        <color rgba="0.0 0.0 0.0 0.8" />
      </material>
    </collision>
    <inertial>
      <mass value="0.5" />
      <inertia ixx="2.8333333e-4" iyy="3.3333333e-5" izz="2.8333333e-4" ixy="0.0" ixz="0.0" iyz="0.0" />
    </inertial>
  </link>

  <joint name="camera_link6_joint" type="fixed">
    <parent link="Link6" />
    <child link="camera_connection" />
    <origin xyz="0.0 -0.058 -0.013" rpy="0.0 0.0 0.0" />
  </joint>

  <link name="camera">
    <visual>
      <origin xyz="0 0 0" rpy="0 0 0" />
      <geometry>
        <box size="0.03 0.03 0.03" />
      </geometry>
      <material name="white">
        <color rgba="1.0 1.0 1.0 0.5" />
      </material>
    </visual>
    <collision>
      <origin xyz="0 0 0" rpy="0 0 0" />
      <geometry>
        <box size="0.03 0.03 0.03" />
      </geometry>
      <material name="white">
        <color rgba="1.0 1.0 1.0 0.5" />
      </material>
    </collision>
    <inertial>
      <mass value="0.1125" />
      <inertia ixx="1.6875e-5" iyy="1.6875e-5" izz="1.6875e-5" ixy="0.0" ixz="0.0" iyz="0.0" />
    </inertial>
  </link>

  <joint name="camera_joint" type="fixed">
    <parent link="camera_connection" />
    <child link="camera" />
    <origin xyz="0.0 -0.045 0.0" rpy="0.0 -1.5708 0.0" />
  </joint>
  
  <!-- 加进来的夹爪扩展，致敬作者：bilibili——关咲_侑 -->
  <link name="robotiq_85_base_link">
    <visual>
      <geometry>
        <mesh filename="package://rm_description/meshes/rm_65_arm/gripper/visual/robotiq_base.dae" />
      </geometry>
    </visual>
    <collision>
      <geometry>
        <mesh filename="package://rm_description/meshes/rm_65_arm/gripper/collision/robotiq_base.stl" />
      </geometry>
    </collision>
    <inertial>
      <origin xyz="0.0 2.274e-05 0.03232288" rpy="0 0 0" />
      <mass value="6.6320197e-01" />
      <!-- <inertia ixx="5.1617816e-04" iyy="5.8802208e-04" izz="3.9462776e-04" ixy="2.936e-8" ixz="0.0" iyz="-3.2296e-7" /> -->
    </inertial>
  </link>

  <link name="robotiq_85_left_knuckle_link">
    <visual>
      <geometry>
        <mesh filename="package://rm_description/meshes/rm_65_arm/gripper/visual/left_knuckle.dae" />
      </geometry>
    </visual>
    <collision>
      <geometry>
        <mesh filename="package://rm_description/meshes/rm_65_arm/gripper/collision/left_knuckle.stl" />
      </geometry>
    </collision>
    <inertial>
      <origin xyz="0.01213197 0.0002 -0.00058647" rpy="0 0 0" />
      <mass value="1.384773208e-02" />
      <!-- <inertia ixx="3.5232e-7" iyy="2.31944e-6" izz="2.23136e-6" ixy="0.0" ixz="1.1744e-7" iyz="0" /> -->
    </inertial>
  </link>

  <link name="robotiq_85_right_knuckle_link">
    <visual>
      <geometry>
        <mesh filename="package://rm_description/meshes/rm_65_arm/gripper/visual/right_knuckle.dae" />
      </geometry>
    </visual>
    <collision>
      <geometry>
        <mesh filename="package://rm_description/meshes/rm_65_arm/gripper/collision/right_knuckle.stl" />
      </geometry>
    </collision>
    <inertial>
      <origin xyz="-0.01213197 0.0002 -0.00058647" rpy="0 0 0" />
      <mass value="1.384773208e-02" />
      <!-- <inertia ixx="3.5232e-7" iyy="2.31944e-6" izz="2.23136e-6" ixy="0.0" ixz="-1.1744e-7" iyz="0.0" /> -->
    </inertial>
  </link>

  <link name="robotiq_85_left_finger_link">
    <visual>
      <geometry>
        <mesh filename="package://rm_description/meshes/rm_65_arm/gripper/visual/left_finger.dae" />
      </geometry>
    </visual>
    <collision>
      <geometry>
        <mesh filename="package://rm_description/meshes/rm_65_arm/gripper/collision/left_finger.stl" />
      </geometry>
    </collision>
    <inertial>
      <origin xyz="0.00346899 -0.00079447 0.01867121" rpy="0 0 0" />
      <mass value="4.260376752e-02" />
      <!-- <inertia ixx="1.385792000000000e-05" iyy="1.183208e-05" izz="5.19672e-06" ixy="0.0" ixz="-2.17264e-06" iyz="0.0" /> -->
    </inertial>
  </link>

  <link name="robotiq_85_right_finger_link">
    <visual>
      <geometry>
        <mesh filename="package://rm_description/meshes/rm_65_arm/gripper/visual/right_finger.dae" />
      </geometry>
    </visual>
    <collision>
      <geometry>
        <mesh filename="package://rm_description/meshes/rm_65_arm/gripper/collision/right_finger.stl" />
      </geometry>
    </collision>
    <inertial>
      <origin xyz="-0.00346899 -5.53e-06 0.01867121" rpy="0 0 0" />
      <mass value="4.260376752000000e-02" />
      <!-- <inertia ixx="1.385792e-05" iyy="1.183208e-05" izz="5.19672e-06" ixy="0.0" ixz="2.17264e-06" iyz="0.0" /> -->
    </inertial>
  </link>

  <link name="robotiq_85_left_inner_knuckle_link">
    <visual>
      <geometry>
        <mesh filename="package://rm_description/meshes/rm_65_arm/gripper/visual/left_inner_knuckle.dae" />
      </geometry>
    </visual>
    <collision>
      <geometry>
        <mesh filename="package://rm_description/meshes/rm_65_arm/gripper/collision/left_inner_knuckle.stl" />
      </geometry>
    </collision>
    <inertial>
      <origin xyz="0.01897699 0.00015001 0.02247101" rpy="0 0 0" />
      <mass value="2.969376448e-02" />
      <!-- <inertia ixx="9.57136e-06" iyy="8.69056e-06" izz="8.19144e-06" ixy="0.0" ixz="-3.93424e-06" iyz="0.0" /> -->
    </inertial>
  </link>

  <link name="robotiq_85_right_inner_knuckle_link">
    <visual>
      <geometry>
        <mesh filename="package://rm_description/meshes/rm_65_arm/gripper/visual/right_inner_knuckle.dae" />
      </geometry>
    </visual>
    <collision>
      <geometry>
        <mesh filename="package://rm_description/meshes/rm_65_arm/gripper/collision/right_inner_knuckle.stl" />
      </geometry>
    </collision>
    <inertial>
      <origin xyz="-0.01926824 5.001e-05 0.02222178" rpy="0 0 0" />
      <mass value="2.969376448e-02" />
      <!-- <inertia ixx="9.42456e-06" iyy="8.69056e-06" izz="8.33824e-06" ixy="0.0" ixz="3.9636e-06" iyz="0.0" /> -->
    </inertial>
  </link>

  <link name="robotiq_85_left_finger_tip_link">
    <visual>
      <geometry>
        <mesh filename="package://rm_description/meshes/rm_65_arm/gripper/visual/left_finger_tip.dae" />
      </geometry>
    </visual>
    <collision>
      <geometry>
        <mesh filename="package://rm_description/meshes/rm_65_arm/gripper/collision/left_finger_tip.stl" />
      </geometry>
      <surface>
        <friction>
          <ode>
            <mu1>100000.0</mu1>
            <mu2>100000.0</mu2>
          </ode>
        </friction>
        <contact>
          <ode>
            <kp>1e+5</kp>
            <kd>1</kd>
            <soft_cfm>0</soft_cfm>
            <soft_erp>0.2</soft_erp>
            <minDepth>0.002</minDepth>
            <maxVel>0</maxVel>
          </ode>
        </contact>
      </surface>
    </collision>
    <inertial>
      <origin xyz="-0.01456706 -0.0008 0.01649701" rpy="0 0 0" />
      <mass value="4.268588744e-02" />
      <!-- <inertia ixx="1.048152e-05" iyy="1.197888e-05" izz="4.22784e-06" ixy="0.0" ixz="3.5232e-6" iyz="0.0" /> -->
    </inertial>
  </link>

  <link name="robotiq_85_right_finger_tip_link">
    <visual>
      <geometry>
        <mesh filename="package://rm_description/meshes/rm_65_arm/gripper/visual/right_finger_tip.dae" />
      </geometry>
    </visual>
    <collision>
      <geometry>
        <mesh filename="package://rm_description/meshes/rm_65_arm/gripper/collision/right_finger_tip.stl" />
      </geometry>
      <surface>
        <friction>
          <ode>
            <mu1>100000.0</mu1>
            <mu2>100000.0</mu2>
          </ode>
        </friction>
        <contact>
          <ode>
            <kp>1e+5</kp>
            <kd>1</kd>
            <soft_cfm>0</soft_cfm>
            <soft_erp>0.2</soft_erp>
            <minDepth>0.002</minDepth>
            <maxVel>0</maxVel>
          </ode>
        </contact>
      </surface>
    </collision>
    <inertial>
      <origin xyz="0.01456706 5e-05 0.01649701" rpy="0 0 0" />
      <mass value="4.268588744e-02" />
      <!-- <inertia ixx="1.048152e-05" iyy="1.197888e-05" izz="4.22784e-06" ixy="0.0" ixz="-3.5232e-06" iyz="0.0" /> -->
    </inertial>
  </link>

  <joint name="robotiq_85_base_joint" type="fixed">
    <parent link="Link6" />
    <child link="robotiq_85_base_link" />
    <axis xyz="0 0 1" />
    <origin xyz="0 0 0" rpy="0 0 0" />
    <limit lower="-3.14" upper="3.14" velocity="1.0" effort="10" />
  </joint>

  <joint name="robotiq_85_left_knuckle_joint" type="revolute">
    <parent link="robotiq_85_base_link" />
    <child link="robotiq_85_left_knuckle_link" />
    <axis xyz="0 -1 0" />
    <origin xyz="0.03060114 0.0 0.05490452" rpy="0 0 0" />
    <limit lower="0.0" upper="0.8" velocity="0.5" effort="50" />
  </joint>

  <joint name="robotiq_85_right_knuckle_joint" type="revolute">
    <parent link="robotiq_85_base_link" />
    <child link="robotiq_85_right_knuckle_link" />
    <axis xyz="0 -1 0" />
    <origin xyz="-0.03060114 0.0 0.05490452" rpy="0 0 0" />
    <limit lower="-0.8" upper="0.0" velocity="0.5" effort="50" />
    <mimic joint="robotiq_85_left_knuckle_joint" multiplier="-1" />
  </joint>

  <joint name="robotiq_85_left_finger_joint" type="fixed">
    <parent link="robotiq_85_left_knuckle_link" />
    <child link="robotiq_85_left_finger_link" />
    <origin xyz="0.03152616 0.0 -0.00376347" rpy="0 0 0" />
  </joint>

  <joint name="robotiq_85_right_finger_joint" type="fixed">
    <parent link="robotiq_85_right_knuckle_link" />
    <child link="robotiq_85_right_finger_link" />
    <origin xyz="-0.03152616 0.0 -0.00376347" rpy="0 0 0" />
  </joint>

  <joint name="robotiq_85_left_inner_knuckle_joint" type="continuous">
    <parent link="robotiq_85_base_link" />
    <child link="robotiq_85_left_inner_knuckle_link" />
    <axis xyz="0 -1 0" />
    <origin xyz="0.0127 0.0 0.06142" rpy="0 0 0" />
    <mimic joint="robotiq_85_left_knuckle_joint" />
  </joint>

  <joint name="robotiq_85_right_inner_knuckle_joint" type="continuous">
    <parent link="robotiq_85_base_link" />
    <child link="robotiq_85_right_inner_knuckle_link" />
    <axis xyz="0 -1 0" />
    <origin xyz="-0.0127 0.0 0.06142" rpy="0 0 0" />
    <mimic joint="robotiq_85_left_knuckle_joint" multiplier="-1" />
  </joint>

  <joint name="robotiq_85_left_finger_tip_joint" type="continuous">
    <parent link="robotiq_85_left_finger_link" />
    <child link="robotiq_85_left_finger_tip_link" />
    <axis xyz="0 -1 0" />
    <origin xyz="0.00563134 0.0 0.04718515" rpy="0 0 0" />
    <mimic joint="robotiq_85_left_knuckle_joint" multiplier="-1" />
  </joint>

  <joint name="robotiq_85_right_finger_tip_joint" type="continuous">
    <parent link="robotiq_85_right_finger_link" />
    <child link="robotiq_85_right_finger_tip_link" />
    <axis xyz="0 -1 0" />
    <origin xyz="-0.00563134 0.0 0.04718515" rpy="0 0 0" />
    <mimic joint="robotiq_85_left_knuckle_joint" />
  </joint>

  <!-- https://github.com/ros-controls/gazebo_ros2_control/issues/173 -->
  <link name="dummy_child1"/>
  <link name="dummy_child2"/>
  <link name="dummy_child3"/>
  <link name="dummy_child4"/>
  <link name="dummy_child5"/>
  <joint name="robotiq_85_right_knuckle_joint_mimic" type="fixed">
    <parent link="robotiq_85_base_link" />
    <child link="dummy_child1" />
  </joint>
  <joint name="robotiq_85_left_inner_knuckle_joint_mimic" type="fixed">
    <parent link="robotiq_85_base_link" />
    <child link="dummy_child2" />
  </joint>
  <joint name="robotiq_85_right_inner_knuckle_joint_mimic" type="fixed">
    <parent link="robotiq_85_base_link" />
    <child link="dummy_child3" />
  </joint>
  <joint name="robotiq_85_left_finger_tip_joint_mimic" type="fixed">
    <parent link="robotiq_85_base_link" />
    <child link="dummy_child4" />
  </joint>
  <joint name="robotiq_85_right_finger_tip_joint_mimic" type="fixed">
    <parent link="robotiq_85_base_link" />
    <child link="dummy_child5" />
  </joint>

</robot>
